<?xml version="1.0" encoding="utf-8"?>
<!-- This URDF was automatically created by SolidWorks to URDF Exporter! Originally created by Stephen Brawner (brawner@gmail.com) 
     Commit Version: 1.6.0-4-g7f85cfe  Build Version: 1.6.7995.38578
     For more information, please see http://wiki.ros.org/sw_urdf_exporter -->
<robot
  name="openmmarm">
  <link name="world"/>
  <joint name="world_joint" type="fixed">
    <parent link="world"/>
    <child link="base_link"/>
    <origin xyz="0 0 0" rpy="0 0 0"/>
  </joint>
  <link
    name="base_link">
    <inertial>
      <origin
        xyz="8.09915022552065E-05 -1.20623919045026E-08 -0.030118633020856"
        rpy="0 0 0" />
      <mass
        value="0.142381483362801" />
      <inertia
        ixx="6.14941902711178E-05"
        ixy="1.85834336563704E-08"
        ixz="1.69303017472949E-08"
        iyy="8.71179432025898E-05"
        iyz="-6.21645929776464E-12"
        izz="8.86745548359769E-05" />
    </inertial>
    <visual>
      <origin
        xyz="0 0 0"
        rpy="0 0 0" />
      <geometry>
        <mesh
          filename="package://openmmarm_description/meshes/base_link.STL" />
      </geometry>
      <material
        name="">
        <color
          rgba="1 1 1 1" />
      </material>
    </visual>
    <collision>
      <origin
        xyz="0 0 0"
        rpy="0 0 0" />
      <geometry>
        <mesh
          filename="package://openmmarm_description/meshes/base_link.STL" />
      </geometry>
    </collision>
  </link>
  <link
    name="link1">
    <inertial>
      <origin
        xyz="0.00833611378384113 0.000345511562131883 0.0187961880262469"
        rpy="0 0 0" />
      <mass
        value="0.036286876852508" />
      <inertia
        ixx="3.35574952089329E-05"
        ixy="6.09403116411057E-19"
        ixz="-2.78919961969183E-06"
        iyy="1.2207181857991E-05"
        iyz="-7.73829152760122E-20"
        izz="3.18191610212386E-05" />
    </inertial>
    <visual>
      <origin
        xyz="0 0 0"
        rpy="0 0 0" />
      <geometry>
        <mesh
          filename="package://openmmarm_description/meshes/link1.STL" />
      </geometry>
      <material
        name="">
        <color
          rgba="1 1 1 1" />
      </material>
    </visual>
    <collision>
      <origin
        xyz="0 0 0"
        rpy="0 0 0" />
      <geometry>
        <mesh
          filename="package://openmmarm_description/meshes/link1.STL" />
      </geometry>
    </collision>
  </link>
  <joint
    name="J1"
    type="continuous">
    <origin
      xyz="0 0 0"
      rpy="0 0 0" />
    <parent
      link="base_link" />
    <child
      link="link1" />
    <axis
      xyz="0 0 1" />
  </joint>
  <link
    name="link2">
    <inertial>
      <origin
        xyz="-3.30291349825984E-15 0.119403040194361 0.0390234775570836"
        rpy="0 0 0" />
      <mass
        value="0.347666847087741" />
      <inertia
        ixx="0.00018245396792744"
        ixy="3.71687458240633E-08"
        ixz="-7.46410358600523E-18"
        iyy="0.000122429431137728"
        iyz="-1.19152487991319E-17"
        izz="0.000210686719084012" />
    </inertial>
    <visual>
      <origin
        xyz="0 0 0"
        rpy="0 0 0" />
      <geometry>
        <mesh
          filename="package://openmmarm_description/meshes/link2.STL" />
      </geometry>
      <material
        name="">
        <color
          rgba="1 1 1 1" />
      </material>
    </visual>
    <collision>
      <origin
        xyz="0 0 0"
        rpy="0 0 0" />
      <geometry>
        <mesh
          filename="package://openmmarm_description/meshes/link2.STL" />
      </geometry>
    </collision>
  </link>
  <joint
    name="J2"
    type="continuous">
    <origin
      xyz="0.0199999999999989 0.0366500000000007 0.0385"
      rpy="1.57079632679487 -1.5707963267949 0" />
    <parent
      link="link1" />
    <child
      link="link2" />
    <axis
      xyz="0 0 1" />
  </joint>
  <link
    name="link3">
    <inertial>
      <origin
        xyz="0.0559014525364826 -0.172833716840443 0.0365839561421469"
        rpy="0 0 0" />
      <mass
        value="0.188758706435604" />
      <inertia
        ixx="0.000139762233972135"
        ixy="9.14197115044133E-06"
        ixz="2.71964714868321E-08"
        iyy="8.1184147067388E-05"
        iyz="5.31902540633526E-10"
        izz="0.00013884603625925" />
    </inertial>
    <visual>
      <origin
        xyz="0 0 0"
        rpy="0 0 0" />
      <geometry>
        <mesh
          filename="package://openmmarm_description/meshes/link3.STL" />
      </geometry>
      <material
        name="">
        <color
          rgba="1 1 1 1" />
      </material>
    </visual>
    <collision>
      <origin
        xyz="0 0 0"
        rpy="0 0 0" />
      <geometry>
        <mesh
          filename="package://openmmarm_description/meshes/link3.STL" />
      </geometry>
    </collision>
  </link>
  <joint
    name="J3"
    type="continuous">
    <origin
      xyz="0 0.238806080405858 0"
      rpy="0 0 0" />
    <parent
      link="link2" />
    <child
      link="link3" />
    <axis
      xyz="0 0 1" />
  </joint>
  <link
    name="link4">
    <inertial>
      <origin
        xyz="6.73831473931264E-05 0.055624792786271 0.0313801437507282"
        rpy="0 0 0" />
      <mass
        value="0.11877187684737" />
      <inertia
        ixx="3.87336878288339E-05"
        ixy="3.33401577033842E-08"
        ixz="2.97140416520765E-08"
        iyy="4.91197302492646E-05"
        iyz="-1.95220028749838E-06"
        izz="3.92911426755369E-05" />
    </inertial>
    <visual>
      <origin
        xyz="0 0 0"
        rpy="0 0 0" />
      <geometry>
        <mesh
          filename="package://openmmarm_description/meshes/link4.STL" />
      </geometry>
      <material
        name="">
        <color
          rgba="1 1 1 1" />
      </material>
    </visual>
    <collision>
      <origin
        xyz="0 0 0"
        rpy="0 0 0" />
      <geometry>
        <mesh
          filename="package://openmmarm_description/meshes/link4.STL" />
      </geometry>
    </collision>
  </link>
  <joint
    name="J4"
    type="continuous">
    <origin
      xyz="0.0616968037972163 -0.254291383775743 0.0366494566851594"
      rpy="0 1.56644675228773 -1.5707963267831" />
    <parent
      link="link3" />
    <child
      link="link4" />
    <axis
      xyz="-0.00434956079241374 0 -0.999990540615717" />
  </joint>
  <link
    name="link5">
    <inertial>
      <origin
        xyz="6.90957312277756E-05 -0.0162029082727128 -0.0302226373686074"
        rpy="0 0 0" />
      <mass
        value="0.118771876898746" />
      <inertia
        ixx="3.8733913039163E-05"
        ixy="-4.18356868745696E-08"
        ixz="2.71031530457421E-08"
        iyy="4.879371829168E-05"
        iyz="-1.95310061424078E-06"
        izz="3.96169294190881E-05" />
    </inertial>
    <visual>
      <origin
        xyz="0 0 0"
        rpy="0 0 0" />
      <geometry>
        <mesh
          filename="package://openmmarm_description/meshes/link5.STL" />
      </geometry>
      <material
        name="">
        <color
          rgba="1 1 1 1" />
      </material>
    </visual>
    <collision>
      <origin
        xyz="0 0 0"
        rpy="0 0 0" />
      <geometry>
        <mesh
          filename="package://openmmarm_description/meshes/link5.STL" />
      </geometry>
    </collision>
  </link>
  <joint
    name="J5"
    type="continuous">
    <origin
      xyz="0.000147885066942065 0.0339999999999768 0.0339996783809576"
      rpy="-1.57079632679422 0 0" />
    <parent
      link="link4" />
    <child
      link="link5" />
    <axis
      xyz="0 0 1" />
    <limit
      lower="0"
      upper="0"
      effort="0"
      velocity="0" />
  </joint>
  <link
    name="link6">
    <inertial>
      <origin
        xyz="0 2.77555756156289E-17 -0.0025"
        rpy="0 0 0" />
      <mass
        value="0.00376849746761364" />
      <inertia
        ixx="3.41714056321192E-07"
        ixy="6.85232324605099E-24"
        ixz="8.27180612553028E-25"
        iyy="3.41714056321192E-07"
        iyz="7.70008600480521E-24"
        izz="6.6772603986066E-07" />
    </inertial>
    <visual>
      <origin
        xyz="0 0 0"
        rpy="0 0 0" />
      <geometry>
        <mesh
          filename="package://openmmarm_description/meshes/link6.STL" />
      </geometry>
      <material
        name="">
        <color
          rgba="1 1 1 1" />
      </material>
    </visual>
    <collision>
      <origin
        xyz="0 0 0"
        rpy="0 0 0" />
      <geometry>
        <mesh
          filename="package://openmmarm_description/meshes/link6.STL" />
      </geometry>
    </collision>
  </link>
  <joint
    name="J6"
    type="continuous">
    <origin
      xyz="0 -0.0435000000000013 -0.0340000000000001"
      rpy="1.5707963267949 0 0" />
    <parent
      link="link5" />
    <child
      link="link6" />
    <axis
      xyz="0 0 -1" />
  </joint>
</robot>